Workbook

Sheet ⚙️ Control
B1: ⚙️ CONTROL CENTRAL — GULA KPIs · Cambia el mes para actualizar todo
B3: 📅 MES ACTIVO → | C3: Feb 2026 | D3: 👈 Selecciona aquí el mes. Todos los datos de ventas y ratios se recalculan solos.
B5: 📋 CÓMO ACTUALIZAR CADA MES
B6: 1. Ir a '📅 Ventas Mensuales' | C6: Añade 4 filas al final de la tabla (una por tienda) con los datos del nuevo mes.
B7: 2. Cambiar Mes Activo aquí (C3) | C7: Todo: ventas, ratios sala/delivery y alertas se recalculan automáticamente.
B8: 3. Revisar '📊 Resumen Global' | C8: Compara las 4 tiendas y ve la evolución del mes.
B9: 4. Actualizar KPIs operativos | C9: En '📈 KPIs Customer Journey' actualiza manualmente tasas de error, ratings, etc.
B10: 5. Ver '🚨 Panel de Alertas' | C10: Semáforos automáticos — actúa sobre los rojos.
B11: 🎨 CÓDIGO DE COLORES
B12: Celda amarilla 🟡 | C12: EDITABLE — datos que introduces tú.
B13: Celda gris 🔘 | C13: FÓRMULA — se calcula sola. No tocar.
B14: Texto azul oscuro | C14: Valor hardcoded / input manual.
B15: Texto verde oscuro | C15: Dato vinculado a ventas reales.

Sheet 📅 Ventas Mensuales
A1: 📅 VENTAS MENSUALES — Datos Reales por Tienda | Añade filas nuevas cada mes al final
A2: MES | B2: TIENDA | C2: SALA / ÁGORA (€) | D2: UBER / DELIVERY (€) | E2: TOTAL (€) | F2: % SALA | G2: % DELIVERY | H2: NOTAS
A3: Mar 2025 | B3: Móstoles | C3: 4160 | D3: 18406.09 | E3: 22566.09 | F3: =IFERROR(C3/E3,0) -> 0.1843474 | G3: =IFERROR(D3/E3,0) -> 0.8156526
A4: Mar 2025 | B4: Valencia | C4: 14420 | D4: 24184.39 | E4: 38604.39 | F4: =IFERROR(C4/E4,0) -> 0.37353265 | G4: =IFERROR(D4/E4,0) -> 0.62646735
A5: Mar 2025 | B5: Cartagena | C5: 2480 | D5: 10431.4 | E5: 12911.4 | F5: =IFERROR(C5/E5,0) -> 0.19207832 | G5: =IFERROR(D5/E5,0) -> 0.80792168
A6: Mar 2025 | B6: Sevilla | C6: 0 | D6: 0 | E6: 0 | F6: =IFERROR(C6/E6,0) -> 0 | G6: =IFERROR(D6/E6,0) -> 0
A8: Abr 2025 | B8: Móstoles | C8: 4090 | D8: 12311.69 | E8: 16401.69 | F8: =IFERROR(C8/E8,0) -> 0.24936455 | G8: =IFERROR(D8/E8,0) -> 0.75063545
A9: Abr 2025 | B9: Valencia | C9: 7380 | D9: 19146.59 | E9: 26526.59 | F9: =IFERROR(C9/E9,0) -> 0.27821141 | G9: =IFERROR(D9/E9,0) -> 0.72178859
A10: Abr 2025 | B10: Cartagena | C10: 2530 | D10: 9855.84 | E10: 12385.84 | F10: =IFERROR(C10/E10,0) -> 0.20426552 | G10: =IFERROR(D10/E10,0) -> 0.79573448
A11: Abr 2025 | B11: Sevilla | C11: 0 | D11: 0 | E11: 0 | F11: =IFERROR(C11/E11,0) -> 0 | G11: =IFERROR(D11/E11,0) -> 0
A13: May 2025 | B13: Móstoles | C13: 5760 | D13: 11106.9 | E13: 16866.9 | F13: =IFERROR(C13/E13,0) -> 0.34149725 | G13: =IFERROR(D13/E13,0) -> 0.65850275
A14: May 2025 | B14: Valencia | C14: 9730 | D14: 11445.79 | E14: 21175.79 | F14: =IFERROR(C14/E14,0) -> 0.45948699 | G14: =IFERROR(D14/E14,0) -> 0.54051301
A15: May 2025 | B15: Cartagena | C15: 2190 | D15: 10196.78 | E15: 12386.78 | F15: =IFERROR(C15/E15,0) -> 0.1768014 | G15: =IFERROR(D15/E15,0) -> 0.8231986
A16: May 2025 | B16: Sevilla | C16: 0 | D16: 0 | E16: 0 | F16: =IFERROR(C16/E16,0) -> 0 | G16: =IFERROR(D16/E16,0) -> 0
... A61: Feb 2026 | B61: Sevilla | C61: 4056.24 | D61: 3263.6 | E61: 7319.84 | F61: =IFERROR(C61/E61,0) -> 0.55414326 | G61: =IFERROR(D61/E61,0) -> 0.44585674
A62: ⬆️ AÑADE AQUÍ los datos del nuevo mes — columnas A (ej: 'Mar 2026') y B (ej: 'Móstoles') deben coincidir exactamente con los valores del selector.

Sheet 📋 Instrucciones
B1: 📋 KPIs Customer Journey — GULA 4 Tiendas
B4: 🗂️ ESTRUCTURA DEL DOCUMENTO
B5: Hoja | C5: Descripción
B6: 📊 Resumen Global | C6: Vista comparativa de las 4 tiendas con KPIs calculados automáticamente.
B7: 🏪 Datos Tiendas | C7: 👉 AQUÍ SE ACTUALIZAN LOS DATOS. Introduce los valores reales de cada tienda. Las celdas amarillas son editables.
B8: 📈 KPIs Customer Journey | C8: Tabla con todos los KPIs por fase y tienda. Actualiza valor actual y fecha. Las fórmulas de estado se calculan solas.
B9: 🚨 Panel de Alertas | C9: Alertas automáticas basadas en los umbrales definidos. Se actualiza al cambiar datos.
B11: 🎨 CÓDIGO DE COLORES
B12: Celda amarilla | C12: EDITABLE — introduce aquí los datos actualizados.
B13: Celda gris claro | C13: FÓRMULA — calculada automáticamente. No editar.
B14: Texto azul oscuro | C14: Valor hardcoded / input manual.
B15: Texto negro | C15: Fórmula calculada.
B17: 🚦 ESTADOS DE KPI
B18: ✅ OK | C18: Valor dentro del objetivo.
B19: ⚠️ ATENCIÓN | C19: Valor próximo al límite, requiere seguimiento.
B20: 🚨 CRÍTICO | C20: Valor fuera del objetivo, acción urgente.
B21: ⬜ SIN DATOS | C21: Dato pendiente de instrumentar o recopilar.
B23: 📅 FRECUENCIA DE ACTUALIZACIÓN
B24: Semanal | C24: Ventas delivery semanales, coste marketing.
B25: Mensual | C25: Ratio sala/delivery, ventas sala mensuales, KPIs operativos.
B26: Puntual | C26: Miembros Club Gula, KPIs de identificación y vinculación.

Sheet 🏪 Datos Tiendas
B1: 🏪 DATOS BASE — 4 TIENDAS GULA · Última actualización: ____________
B2: 📝 Celdas AMARILLAS = editables | Celdas VERDES = vinculadas a Ventas Mensuales | Cambia el mes en ⚙️ Control
B3: CAMPO | C3: Móstoles | D3: Valencia | E3: Cartagena | F3: Sevilla | G3: PROMEDIO RED | H3: OBJETIVO RED
B4: 1. DATOS GENERALES Y TIER
B5: Tier actual | C5: Tier 3 | D5: Tier 1/2 | E5: Tier 3+ | F5: Tier 2
B6: Tier objetivo | C6: Tier 2 → Tier 1 | D6: Tier 1 (consolidar) | E6: Tier 3 (30% sala) | F6: Tier 1
B7: Estado (OK / ATENCIÓN / CRÍTICO) | C7: ATENCIÓN | D7: OK | E7: CRÍTICO | F7: ATENCIÓN
B9: 2. RATIO SALA / DELIVERY (%)
B10: % Sala — anual | C10: 41 | D10: 55 | E10: 20 | F10: 55 | G10: =AVERAGE(C10,D10,E10,F10) -> 42.75 | H10: Ref: ≥50% (Tier 2)
B11: % Delivery — anual | C11: 59 | D11: 45 | E11: 80 | F11: 45 | G11: =AVERAGE(C11,D11,E11,F11) -> 57.25
B12: % Sala — mes activo (calculado de ventas reales) | C12: =IFERROR(ROUND(SUMIFS('📅 Ventas Mensuales'!$C:$C,'📅 Ventas Mensuales'!$A:$A,'⚙️ Control'!$C$3,'📅 Ventas Mensuales'!$B:$B,"Móstoles")/SUMIFS('📅 Ventas Mensuales'!$E:$E,'📅 Ventas Mensuales'!$A:$A,'⚙️ Control'!$C$3,'📅 Ventas Mensuales'!$B:$B,"Móstoles")*100,1),0) -> 35.8 | D12: =IFERROR(ROUND(SUMIFS('📅 Ventas Mensuales'!$C:$C,'📅 Ventas Mensuales'!$A:$A,'⚙️ Control'!$C$3,'📅 Ventas Mensuales'!$B:$B,"Valencia")/SUMIFS('📅 Ventas Mensuales'!$E:$E,'📅 Ventas Mensuales'!$A:$A,'⚙️ Control'!$C$3,'📅 Ventas Mensuales'!$B:$B,"Valencia")*100,1),0) -> 42.4 | E12: =IFERROR(ROUND(SUMIFS('📅 Ventas Mensuales'!$C:$C,'📅 Ventas Mensuales'!$A:$A,'⚙️ Control'!$C$3,'📅 Ventas Mensuales'!$B:$B,"Cartagena")/SUMIFS('📅 Ventas Mensuales'!$E:$E,'📅 Ventas Mensuales'!$A:$A,'⚙️ Control'!$C$3,'📅 Ventas Mensuales'!$B:$B,"Cartagena")*100,1),0) -> 18.3 | F12: =IFERROR(ROUND(SUMIFS('📅 Ventas Mensuales'!$C:$C,'📅 Ventas Mensuales'!$A:$A,'⚙️ Control'!$C$3,'📅 Ventas Mensuales'!$B:$B,"Sevilla")/SUMIFS('📅 Ventas Mensuales'!$E:$E,'📅 Ventas Mensuales'!$A:$A,'⚙️ Control'!$C$3,'📅 Ventas Mensuales'!$B:$B,"Sevilla")*100,1),0) -> 55.4 | G12: =AVERAGE(C12,D12,E12,F12) -> 37.975
B13: % Delivery — mes activo (calculado de ventas reales) | C13: =IFERROR(100-C12,0) -> 64.2 | D13: =IFERROR(100-D12,0) -> 57.6 | E13: =IFERROR(100-E12,0) -> 81.7 | F13: =IFERROR(100-F12,0) -> 44.6 | G13: =AVERAGE(C13,D13,E13,F13) -> 62.025
B14: 🎯 OBJETIVO sala — 30 mayo | C14: 70 | D14: 70 | E14: 30 | F14: 70
B15: Gap vs objetivo (pp a recuperar) | C15: =MAX(0,C14-C12) -> 34.2 | D15: =MAX(0,D14-D12) -> 27.6 | E15: =MAX(0,E14-E12) -> 11.7 | F15: =MAX(0,F14-F12) -> 14.6 | G15: =AVERAGE(C15,D15,E15,F15) -> 22.025 | H15: → Menor = mejor
B17: 3. COSTES Y MÁRGENES DELIVERY (%)
B18: Coste marketing delivery (% s/ventas brutas) | C18: 19 | D18: 24 | E18: 43 | F18: 42 | G18: =AVERAGE(C18,D18,E18,F18) -> 32 | H18: Obj red: ≤22%
B19: Margen neto delivery (%) | C19: 60 | D19: 55 | E19: 40 | F19: 40 | G19: =AVERAGE(C19,D19,E19,F19) -> 48.75 | H19: Obj: ≥55%
B21: 4. VENTAS (€) — ✅ Vinculadas a Ventas Mensuales
B22: Ventas delivery semanales (€ estimado) | C22: 1100 | D22: 1276 | E22: 575 | F22: 1310 | G22: =IFERROR(G23/4.3,"") -> 3497.7395 | H22: ≈ mensual / 4.3 semanas
B23: Ventas delivery mensuales (€) | C23: =IFERROR(SUMIFS('📅 Ventas Mensuales'!$D:$D,'📅 Ventas Mensuales'!$A:$A,'⚙️ Control'!$C$3,'📅 Ventas Mensuales'!$B:$B,"Móstoles"),0) -> 4371.63 | D23: =IFERROR(SUMIFS('📅 Ventas Mensuales'!$D:$D,'📅 Ventas Mensuales'!$A:$A,'⚙️ Control'!$C$3,'📅 Ventas Mensuales'!$B:$B,"Valencia"),0) -> 5104.3 | E23: =IFERROR(SUMIFS('📅 Ventas Mensuales'!$D:$D,'📅 Ventas Mensuales'!$A:$A,'⚙️ Control'!$C$3,'📅 Ventas Mensuales'!$B:$B,"Cartagena"),0) -> 2300.75 | F23: =IFERROR(SUMIFS('📅 Ventas Mensuales'!$D:$D,'📅 Ventas Mensuales'!$A:$A,'⚙️ Control'!$C$3,'📅 Ventas Mensuales'!$B:$B,"Sevilla"),0) -> 3263.6 | G23: =SUM(C23,D23,E23,F23) -> 15040.28 | H23: Total red
B24: Ventas sala mensuales (€) | C24: =IFERROR(SUMIFS('📅 Ventas Mensuales'!$C:$C,'📅 Ventas Mensuales'!$A:$A,'⚙️ Control'!$C$3,'📅 Ventas Mensuales'!$B:$B,"Móstoles"),0) -> 2438.2 | D24: =IFERROR(SUMIFS('📅 Ventas Mensuales'!$C:$C,'📅 Ventas Mensuales'!$A:$A,'⚙️ Control'!$C$3,'📅 Ventas Mensuales'!$B:$B,"Valencia"),0) -> 3751.1 | E24: =IFERROR(SUMIFS('📅 Ventas Mensuales'!$C:$C,'📅 Ventas Mensuales'!$A:$A,'⚙️ Control'!$C$3,'📅 Ventas Mensuales'!$B:$B,"Cartagena"),0) -> 514.45 | F24: =IFERROR(SUMIFS('📅 Ventas Mensuales'!$C:$C,'📅 Ventas Mensuales'!$A:$A,'⚙️ Control'!$C$3,'📅 Ventas Mensuales'!$B:$B,"Sevilla"),0) -> 4056.24 | G24: =SUM(C24,D24,E24,F24) -> 10759.99 | H24: Total red
B25: Ventas totales mensuales (sala + delivery) (€) | C25: =C24+C23 -> 6809.83 | D25: =D24+D23 -> 8855.4 | E25: =E24+E23 -> 2815.2 | F25: =F24+F23 -> 7319.84 | G25: =SUM(C25,D25,E25,F25) -> 25800.27 | H25: Total red
B27: 5. KPIs CORPORATIVOS (gestionados por Central)
B28: Followers Instagram (total red) | C28: n/d — pendiente instrumentar | G28: Obj: +10% (30 mayo)
B29: Miembros Club Gula (acumulado red) | C29: 0 | G29: Obj: ≥100/tienda (30 mayo)
B30: % pedidos canal propio (toda la red) | C30: ~0% | G30: Obj: 5% en 6 meses

Sheet 📈 KPIs Customer Journey
B1: 📈 KPIs CUSTOMER JOURNEY — GULA · 7 Fases · 4 Tiendas
B2: 📝 Actualiza las columnas VALOR ACTUAL, PROGRESO % y FECHA. El ESTADO se calcula solo. Celdas amarillas = editables.
B3: TIENDA | C3: FASE | D3: KPI | E3: VALOR ACTUAL | F3: OBJETIVO | G3: PROGRESO % | H3: ESTADO | I3: RESPONSABLE | J3: FECHA ACTUALIZ. | K3: NOTAS
B4: Sevilla | C4: 1. Captación | D4: Tasa conversión menú (vistas→pedidos) | E4: 5% | F4: ≥8% | G4: 45 | H4: =IF(G4="","⬜ SIN DATOS",IF(G4>=85,"✅ OK",IF(G4>=40,"⚠️ ATENCIÓN","🚨 CRÍTICO"))) -> ⚠️ ATENCIÓN | I4: Central | K4: 36.2K vistas, 247 pedidos (Uber Sevilla)
B5: Móstoles | C5: 1. Captación | D5: Tasa conversión menú (vistas→pedidos) | E5: n/d | F5: ≥8% | G5: 0 | H5: =IF(G5="","⬜ SIN DATOS",IF(G5>=85,"✅ OK",IF(G5>=40,"⚠️ ATENCIÓN","🚨 CRÍTICO"))) -> 🚨 CRÍTICO | I5: Central | K5: Pendiente extraer de dashboard Uber/Glovo
B6: Valencia | C6: 1. Captación | D6: Tasa conversión menú (vistas→pedidos) | E6: n/d | F6: ≥8% | G6: 0 | H6: =IF(G6="","⬜ SIN DATOS",IF(G6>=85,"✅ OK",IF(G6>=40,"⚠️ ATENCIÓN","🚨 CRÍTICO"))) -> 🚨 CRÍTICO | I6: Central | K6: Pendiente extraer de dashboard Uber/Glovo
B7: Cartagena | C7: 1. Captación | D7: Tasa conversión menú (vistas→pedidos) | E7: n/d | F7: ≥8% | G7: 0 | H7: =IF(G7="","⬜ SIN DATOS",IF(G7>=85,"✅ OK",IF(G7>=40,"⚠️ ATENCIÓN","🚨 CRÍTICO"))) -> 🚨 CRÍTICO | I7: Central | K7: Pendiente extraer de dashboard Uber/Glovo
B8: Móstoles | C8: 1. Captación | D8: Coste marketing delivery (% s/ventas) | E8: 19% | F8: ≤20% | G8: 92 | H8: =IF(G8="","⬜ SIN DATOS",IF(G8>=85,"✅ OK",IF(G8>=40,"⚠️ ATENCIÓN","🚨 CRÍTICO"))) -> ✅ OK | I8: Compartido | K8: Mejor ratio red — benchmark interno
B9: Valencia | C9: 1. Captación | D9: Coste marketing delivery (% s/ventas) | E9: 24% | F9: ≤20% | G9: 65 | H9: =IF(G9="","⬜ SIN DATOS",IF(G9>=85,"✅ OK",IF(G9>=40,"⚠️ ATENCIÓN","🚨 CRÍTICO"))) -> ⚠️ ATENCIÓN | I9: Compartido | K9: Margen correcto, con recorrido a bajar
B10: Cartagena | C10: 1. Captación | D10: Coste marketing delivery (% s/ventas) | E10: 43% | F10: ≤25% (6m)→≤20% | G10: 15 | H10: =IF(G10="","⬜ SIN DATOS",IF(G10>=85,"✅ OK",IF(G10>=40,"⚠️ ATENCIÓN","🚨 CRÍTICO"))) -> 🚨 CRÍTICO | I10: Compartido | K10: CRÍTICO — insostenible a largo plazo
B11: Sevilla | C11: 1. Captación | D11: Coste marketing delivery (% s/ventas) | E11: 42% | F11: ≤25% (6m)→≤20% | G11: 15 | H11: =IF(G11="","⬜ SIN DATOS",IF(G11>=85,"✅ OK",IF(G11>=40,"⚠️ ATENCIÓN","🚨 CRÍTICO"))) -> 🚨 CRÍTICO | I11: Compartido | K11: Apertura — requiere plan bajada a 6 meses
B12: Todas | C12: 1. Captación | D12: CPO — coste por pedido (€) | E12: n/d | F12: ≤€1.80 | G12: 0 | H12: =IF(G12="","⬜ SIN DATOS",IF(G12>=85,"✅ OK",IF(G12>=40,"⚠️ ATENCIÓN","🚨 CRÍTICO"))) -> 🚨 CRÍTICO | I12: Central | K12: Requiere nº pedidos desde plataforma
B13: Todas | C13: 1. Captación | D13: % pedidos con promoción vs orgánicos | E13: n/d | F13: Medir semanalmente | G13: 0 | H13: =IF(G13="","⬜ SIN DATOS",IF(G13>=85,"✅ OK",IF(G13>=40,"⚠️ ATENCIÓN","🚨 CRÍTICO"))) -> 🚨 CRÍTICO | I13: Central | K13: Disponible en dashboard Uber/Glovo
B14: Sevilla | C14: 2. Primera Experiencia | D14: Tasa de errores (chargebacks/pedidos) | E14: 8.3% | F14: <5% | G14: 25 | H14: =IF(G14="","⬜ SIN DATOS",IF(G14>=85,"✅ OK",IF(G14>=40,"⚠️ ATENCIÓN","🚨 CRÍTICO"))) -> 🚨 CRÍTICO | I14: Franquiciado | K14: CRÍTICO — 22 pedidos con error (Uber Sevilla)
B15: Móstoles | C15: 2. Primera Experiencia | D15: Tasa de errores (chargebacks/pedidos) | E15: n/d | F15: <5% | G15: 0 | H15: =IF(G15="","⬜ SIN DATOS",IF(G15>=85,"✅ OK",IF(G15>=40,"⚠️ ATENCIÓN","🚨 CRÍTICO"))) -> 🚨 CRÍTICO | I15: Franquiciado | K15: Disponible en panel Uber/Glovo
... B26: Todas | C26: 3. Identificación | D26: Tasa conversión anónimo → Club Gula | E26: ~0% | F26: ≥10% en 6 meses | G26: 2 | H26: =IF(G26="","⬜ SIN DATOS",IF(G26>=85,"✅ OK",IF(G26>=40,"⚠️ ATENCIÓN","🚨 CRÍTICO"))) -> 🚨 CRÍTICO | I26: Central | K26: Sin QR activo aún
B27: Todas | C27: 3. Identificación | D27: Coste de identificación (€/nuevo miembro) | E27: n/d | F27: ≤€3 por registro | H27: =IF(G27="","⬜ SIN DATOS",IF(G27>=85,"✅ OK",IF(G27>=40,"⚠️ ATENCIÓN","🚨 CRÍTICO"))) -> ⬜ SIN DATOS | I27: Central | K27: Benchmark: cupón bienvenida
B28: Todas | C28: 3. Identificación | D28: Tiempo hasta identificación (días desde 1er pedido) | E28: n/d | F28: ≤7 días | H28: =IF(G28="","⬜ SIN DATOS",IF(G28>=85,"✅ OK",IF(G28>=40,"⚠️ ATENCIÓN","🚨 CRÍTICO"))) -> ⬜ SIN DATOS | I28: Central | K28: Requiere QR en packaging
B29: Todas | C29: 4. Entrada Ecosistema | D29: Open rate comunicaciones bienvenida (WhatsApp) | E29: n/d | F29: ≥40% | H29: =IF(G29="","⬜ SIN DATOS",IF(G29>=85,"✅ OK",IF(G29>=40,"⚠️ ATENCIÓN","🚨 CRÍTICO"))) -> ⬜ SIN DATOS | I29: Central | K29: Requiere activación chatbot Thomas
B30: Todas | C30: 4. Entrada Ecosistema | D30: % miembros con 2.º pedido en canal propio | E30: n/d | F30: ≥20% | H30: =IF(G30="","⬜ SIN DATOS",IF(G30>=85,"✅ OK",IF(G30>=40,"⚠️ ATENCIÓN","🚨 CRÍTICO"))) -> ⬜ SIN DATOS | I30: Central | K30: KPI clave de transición
B31: Todas | C31: 4. Entrada Ecosistema | D31: Tiempo hasta 1er pedido fuera plataforma (días) | E31: n/d | F31: ≤21 días | H31: =IF(G31="","⬜ SIN DATOS",IF(G31>=85,"✅ OK",IF(G31>=40,"⚠️ ATENCIÓN","🚨 CRÍTICO"))) -> ⬜ SIN DATOS | I31: Central | K31: Desde registro al Club Gula
B32: Todas | C32: 4. Entrada Ecosistema | D32: % clientes que conocen el canal propio | E32: n/d | F32: Encuesta mensual | H32: =IF(G32="","⬜ SIN DATOS",IF(G32>=85,"✅ OK",IF(G32>=40,"⚠️ ATENCIÓN","🚨 CRÍTICO"))) -> ⬜ SIN DATOS | I32: Central | K32: Encuesta en registro al Club
B33: Móstoles | C33: 5. Migración Sala/Canal | D33: % ventas sala vs delivery (ratio actual) | E33: 52% | F33: 70% sala · 30 mayo | G33: 74 | H33: =IF(G33="","⬜ SIN DATOS",IF(G33>=85,"✅ OK",IF(G33>=40,"⚠️ ATENCIÓN","🚨 CRÍTICO"))) -> ⚠️ ATENCIÓN | I33: Franquiciado | K33: Diferencia: 18pp para objetivo
B34: Valencia | C34: 5. Migración Sala/Canal | D34: % ventas sala vs delivery (ratio actual) | E34: 68% | F34: 70% sala · 30 mayo | G34: 97 | H34: =IF(G34="","⬜ SIN DATOS",IF(G34>=85,"✅ OK",IF(G34>=40,"⚠️ ATENCIÓN","🚨 CRÍTICO"))) -> ✅ OK | I34: Franquiciado | K34: Casi en objetivo — consolidar
B35: Cartagena | C35: 5. Migración Sala/Canal | D35: % ventas sala vs delivery (ratio actual) | E35: 24% | F35: 30% sala · 30 mayo | G35: 80 | H35: =IF(G35="","⬜ SIN DATOS",IF(G35>=85,"✅ OK",IF(G35>=40,"⚠️ ATENCIÓN","🚨 CRÍTICO"))) -> ⚠️ ATENCIÓN | I35: Franquiciado | K35: Sala muy limitada — reto físico
B36: Sevilla | C36: 5. Migración Sala/Canal | D36: % ventas sala vs delivery (ratio actual) | E36: 55% | F36: 70% sala · 30 mayo | G36: 79 | H36: =IF(G36="","⬜ SIN DATOS",IF(G36>=85,"✅ OK",IF(G36>=40,"⚠️ ATENCIÓN","🚨 CRÍTICO"))) -> ⚠️ ATENCIÓN | I36: Franquiciado | K36: Buen arranque en apertura
B37: Móstoles | C37: 5. Migración Sala/Canal | D37: Ventas sala mensuales (€) | E37: €4.710 | F37: ≥€7.000/mes | G37: 67 | H37: =IF(G37="","⬜ SIN DATOS",IF(G37>=85,"✅ OK",IF(G37>=40,"⚠️ ATENCIÓN","🚨 CRÍTICO"))) -> ⚠️ ATENCIÓN | I37: Franquiciado | K37: Feb 2026
B38: Valencia | C38: 5. Migración Sala/Canal | D38: Ventas sala mensuales (€) | E38: €10.780 | F38: ≥€12.000/mes | G38: 90 | H38: =IF(G38="","⬜ SIN DATOS",IF(G38>=85,"✅ OK",IF(G38>=40,"⚠️ ATENCIÓN","🚨 CRÍTICO"))) -> ✅ OK | I38: Franquiciado | K38: Feb 2026
B39: Cartagena | C39: 5. Migración Sala/Canal | D39: Ventas sala mensuales (€) | E39: €722 | F39: ≥€2.000/mes | G39: 36 | H39: =IF(G39="","⬜ SIN DATOS",IF(G39>=85,"✅ OK",IF(G39>=40,"⚠️ ATENCIÓN","🚨 CRÍTICO"))) -> 🚨 CRÍTICO | I39: Franquiciado | K39: Feb 2026 — CRÍTICO
B40: Sevilla | C40: 5. Migración Sala/Canal | D40: Ventas sala mensuales (€) | E40: €4.056 | F40: ≥€5.000/mes | G40: 81 | H40: =IF(G40="","⬜ SIN DATOS",IF(G40>=85,"✅ OK",IF(G40>=40,"⚠️ ATENCIÓN","🚨 CRÍTICO"))) -> ⚠️ ATENCIÓN | I40: Franquiciado | K40: Feb 2026
B41: Todas | C41: 5. Migración Sala/Canal | D41: % pedidos fuera de plataforma (canal propio) | E41: ~0% | F41: 5% en 6m / 20% en 18m | G41: 1 | H41: =IF(G41="","⬜ SIN DATOS",IF(G41>=85,"✅ OK",IF(G41>=40,"⚠️ ATENCIÓN","🚨 CRÍTICO"))) -> 🚨 CRÍTICO | I41: Central | K41: Baseline con chatbot Thomas
B42: Valencia | C42: 5. Migración Sala/Canal | D42: GMV canal propio semanal | E42: n/d | F42: ≥€300/sem | H42: =IF(G42="","⬜ SIN DATOS",IF(G42>=85,"✅ OK",IF(G42>=40,"⚠️ ATENCIÓN","🚨 CRÍTICO"))) -> ⬜ SIN DATOS | I42: Central | K42: Pendiente activación chatbot
B43: Móstoles | C43: 5. Migración Sala/Canal | D43: GMV canal propio semanal | E43: n/d | F43: ≥€250/sem | H43: =IF(G43="","⬜ SIN DATOS",IF(G43>=85,"✅ OK",IF(G43>=40,"⚠️ ATENCIÓN","🚨 CRÍTICO"))) -> ⬜ SIN DATOS | I43: Central | K43: Pendiente activación chatbot
B44: Cartagena | C44: 5. Migración Sala/Canal | D44: GMV canal propio semanal | E44: n/d | F44: ≥€150/sem | H44: =IF(G44="","⬜ SIN DATOS",IF(G44>=85,"✅ OK",IF(G44>=40,"⚠️ ATENCIÓN","🚨 CRÍTICO"))) -> ⬜ SIN DATOS | I44: Central | K44: Pendiente activación chatbot
B45: Sevilla | C45: 5. Migración Sala/Canal | D45: GMV canal propio semanal | E45: n/d | F45: ≥€150/sem | H45: =IF(G45="","⬜ SIN DATOS",IF(G45>=85,"✅ OK",IF(G45>=40,"⚠️ ATENCIÓN","🚨 CRÍTICO"))) -> ⬜ SIN DATOS | I45: Central | K45: Pendiente activación chatbot
B46: Todas | C46: 6. Recurrencia | D46: Frecuencia de compra (pedidos/cliente/mes) | E46: n/d | F46: ≥1.5 pedidos/mes | H46: =IF(G46="","⬜ SIN DATOS",IF(G46>=85,"✅ OK",IF(G46>=40,"⚠️ ATENCIÓN","🚨 CRÍTICO"))) -> ⬜ SIN DATOS | I46: Central | K46: Requiere Club Gula activo
B47: Todas | C47: 6. Recurrencia | D47: Tasa recompra 30 días (clientes que repiten) | E47: n/d | F47: ≥20% | H47: =IF(G47="","⬜ SIN DATOS",IF(G47>=85,"✅ OK",IF(G47>=40,"⚠️ ATENCIÓN","🚨 CRÍTICO"))) -> ⬜ SIN DATOS | I47: Central | K47: Segmentar en Uber
B48: Todas | C48: 6. Recurrencia | D48: LTV estimado (€/cliente/año) | E48: n/d | F48: >€200/año | H48: =IF(G48="","⬜ SIN DATOS",IF(G48>=85,"✅ OK",IF(G48>=40,"⚠️ ATENCIÓN","🚨 CRÍTICO"))) -> ⬜ SIN DATOS | I48: Central | K48: Ticket ~€20–31 × frecuencia × meses
B49: Móstoles | C49: 6. Recurrencia | D49: Ventas delivery semanales (promedio 4 semanas, €) | E49: ~€1.100 | F49: ≥€1.400/sem | G49: 79 | H49: =IF(G49="","⬜ SIN DATOS",IF(G49>=85,"✅ OK",IF(G49>=40,"⚠️ ATENCIÓN","🚨 CRÍTICO"))) -> ⚠️ ATENCIÓN | I49: Franquiciado | K49: Dato estimado
B50: Valencia | C50: 6. Recurrencia | D50: Ventas delivery semanales (promedio 4 semanas, €) | E50: ~€1.276 | F50: ≥€1.500/sem | G50: 85 | H50: =IF(G50="","⬜ SIN DATOS",IF(G50>=85,"✅ OK",IF(G50>=40,"⚠️ ATENCIÓN","🚨 CRÍTICO"))) -> ✅ OK | I50: Franquiciado | K50: Dato estimado
...

Sheet 📊 Resumen Global
B1: 📊 RESUMEN GLOBAL — KPIs GULA 4 Tiendas · Mes activo: ver ⚙️ Control
B2: ⚡ Todos los valores se calculan automáticamente desde la hoja '🏪 Datos Tiendas'. No editar aquí.
B3: KPI | C3: Móstoles | D3: Valencia | E3: Cartagena | F3: Sevilla | G3: PROMEDIO / TOTAL RED
B4: TIER Y RATIO SALA / DELIVERY
B5: Tier actual | C5: ='🏪 Datos Tiendas'!C4 -> 0 | D5: ='🏪 Datos Tiendas'!D4 -> 0 | E5: ='🏪 Datos Tiendas'!E4 -> 0 | F5: ='🏪 Datos Tiendas'!F4 -> 0
B6: Tier objetivo | C6: ='🏪 Datos Tiendas'!C5 -> Tier 3 | D6: ='🏪 Datos Tiendas'!D5 -> Tier 1/2 | E6: ='🏪 Datos Tiendas'!E5 -> Tier 3+ | F6: ='🏪 Datos Tiendas'!F5 -> Tier 2
B7: % Sala anual | C7: ='🏪 Datos Tiendas'!C10 -> 41 | D7: ='🏪 Datos Tiendas'!D10 -> 55 | E7: ='🏪 Datos Tiendas'!E10 -> 20 | F7: ='🏪 Datos Tiendas'!F10 -> 55 | G7: =IFERROR(AVERAGE(C7,D7,E7,F7),"") -> 42.75
B8: % Sala — Feb 2026 (reciente) | C8: ='🏪 Datos Tiendas'!C12 -> 35.8 | D8: ='🏪 Datos Tiendas'!D12 -> 42.4 | E8: ='🏪 Datos Tiendas'!E12 -> 18.3 | F8: ='🏪 Datos Tiendas'!F12 -> 55.4 | G8: =IFERROR(AVERAGE(C8,D8,E8,F8),"") -> 37.975
B9: 🎯 Objetivo sala — 30 mayo | C9: ='🏪 Datos Tiendas'!C14 -> 70 | D9: ='🏪 Datos Tiendas'!D14 -> 70 | E9: ='🏪 Datos Tiendas'!E14 -> 30 | F9: ='🏪 Datos Tiendas'!F14 -> 70 | G9: =IFERROR(AVERAGE(C9,D9,E9,F9),"") -> 60
B10: Gap vs objetivo (pp a recuperar) | C10: ='🏪 Datos Tiendas'!C15 -> 34.2 | D10: ='🏪 Datos Tiendas'!D15 -> 27.6 | E10: ='🏪 Datos Tiendas'!E15 -> 11.7 | F10: ='🏪 Datos Tiendas'!F15 -> 14.6 | G10: =IFERROR(AVERAGE(C10,D10,E10,F10),"") -> 22.025
B11: COSTES Y MÁRGENES DELIVERY
B12: Coste marketing delivery (%) | C12: ='🏪 Datos Tiendas'!C18 -> 19 | D12: ='🏪 Datos Tiendas'!D18 -> 24 | E12: ='🏪 Datos Tiendas'!E18 -> 43 | F12: ='🏪 Datos Tiendas'!F18 -> 42 | G12: =IFERROR(AVERAGE(C12,D12,E12,F12),"") -> 32
B13: Margen neto delivery (%) | C13: ='🏪 Datos Tiendas'!C19 -> 60 | D13: ='🏪 Datos Tiendas'!D19 -> 55 | E13: ='🏪 Datos Tiendas'!E19 -> 40 | F13: ='🏪 Datos Tiendas'!F19 -> 40 | G13: =IFERROR(AVERAGE(C13,D13,E13,F13),"") -> 48.75
B14: VENTAS
B15: Ventas delivery semanales (€) | C15: ='🏪 Datos Tiendas'!C22 -> 1100 | D15: ='🏪 Datos Tiendas'!D22 -> 1276 | E15: ='🏪 Datos Tiendas'!E22 -> 575 | F15: ='🏪 Datos Tiendas'!F22 -> 1310 | G15: =IFERROR(SUM(C15,D15,E15,F15),"") -> 4261
B16: Ventas delivery mensuales (€) | C16: ='🏪 Datos Tiendas'!C23 -> 4371.63 | D16: ='🏪 Datos Tiendas'!D23 -> 5104.3 | E16: ='🏪 Datos Tiendas'!E23 -> 2300.75 | F16: ='🏪 Datos Tiendas'!F23 -> 3263.6 | G16: =IFERROR(SUM(C16,D16,E16,F16),"") -> 15040.28
B17: Ventas sala mensuales (€) | C17: ='🏪 Datos Tiendas'!C24 -> 2438.2 | D17: ='🏪 Datos Tiendas'!D24 -> 3751.1 | E17: ='🏪 Datos Tiendas'!E24 -> 514.45 | F17: ='🏪 Datos Tiendas'!F24 -> 4056.24 | G17: =IFERROR(SUM(C17,D17,E17,F17),"") -> 10759.99
B18: Ventas totales mensuales (€) | C18: ='🏪 Datos Tiendas'!C25 -> 6809.83 | D18: ='🏪 Datos Tiendas'!D25 -> 8855.4 | E18: ='🏪 Datos Tiendas'!E25 -> 2815.2 | F18: ='🏪 Datos Tiendas'!F25 -> 7319.84 | G18: =IFERROR(SUM(C18,D18,E18,F18),"") -> 25800.27

Sheet 🚨 Panel de Alertas
B1: 🚨 PANEL DE ALERTAS — Calculado automáticamente desde Datos Tiendas
B2: Los semáforos se actualizan solos al cambiar los datos en '🏪 Datos Tiendas'
B3: TIENDA | C3: ALERTA | D3: VALOR ACTUAL | E3: UMBRAL | F3: ESTADO | G3: ACCIÓN
B4: Cartagena | C4: Coste marketing delivery | D4: ='🏪 Datos Tiendas'!E18 -> 43 | E4: ≤25% (6m) | F4: 🚨 CRÍTICO | G4: Revisar estructura descuentos Uber/Glovo URGENTE
B5: Sevilla | C5: Coste marketing delivery | D5: ='🏪 Datos Tiendas'!F18 -> 42 | E5: ≤25% (6m) | F5: ⚠️ ATENCIÓN | G5: Plan bajada a 6 meses — normal en apertura
B6: Valencia | C6: Coste marketing delivery | D6: ='🏪 Datos Tiendas'!D18 -> 24 | E6: ≤20% | F6: ⚠️ ATENCIÓN | G6: Recorrido a bajar del 24% al 20%
B7: Cartagena | C7: % Sala (gap objetivo 30 mayo) | D7: ='🏪 Datos Tiendas'!E15 -> 11.7 | E7: 0pp idealmente | F7: 🚨 CRÍTICO | G7: Sala muy limitada — canal propio como alternativa
B8: Móstoles | C8: % Sala (gap objetivo 30 mayo) | D8: ='🏪 Datos Tiendas'!C15 -> 34.2 | E8: 0pp idealmente | F8: ⚠️ ATENCIÓN | G8: Estacionalidad invernal — construir hábito sala
B9: Red entera | C9: Club Gula — miembros | D9: ='🏪 Datos Tiendas'!C29 -> 0 | E9: ≥100/tienda | F9: 🚨 CRÍTICO | G9: Lanzar programa QR + landing urgente
B10: Sevilla | C10: Unfulfilled rate | D10: 1.85% | E10: <0.8% | F10: 🚨 CRÍTICO | G10: Activar aceptación automática + reducir timeout
B11: Sevilla | C11: Tasa errores (chargebacks) | D11: 8.3% | E11: <5% | F11: 🚨 CRÍTICO | G11: Implementar checklist embolsado + protocolo
B12: Red entera | C12: % pedidos canal propio | D12: ~0% | E12: 5% en 6 meses | F12: 🚨 CRÍTICO | G12: Activar chatbot Thomas — test en Móstoles
B13: Cartagena | C13: Ventas delivery (tendencia) | D13: ~€575/sem | E13: ≥€900/sem | F13: ⚠️ ATENCIÓN | G13: Caída respecto Q4 2025 — revisar mix promo
